[2023-08-17T00:11:08.201+0300] {taskinstance.py:1103} INFO - Dependencies all met for dep_context=non-requeueable deps ti=<TaskInstance: dag_data_lake.is_api_ready_to_consumes manual__2023-08-16T06:32:20.224820+00:00 [queued]>
[2023-08-17T00:11:08.242+0300] {taskinstance.py:1103} INFO - Dependencies all met for dep_context=requeueable deps ti=<TaskInstance: dag_data_lake.is_api_ready_to_consumes manual__2023-08-16T06:32:20.224820+00:00 [queued]>
[2023-08-17T00:11:08.243+0300] {taskinstance.py:1308} INFO - Starting attempt 1 of 3
[2023-08-17T00:11:08.363+0300] {taskinstance.py:1327} INFO - Executing <Task(HttpSensor): is_api_ready_to_consumes> on 2023-08-16 06:32:20.224820+00:00
[2023-08-17T00:11:08.452+0300] {standard_task_runner.py:57} INFO - Started process 234163 to run task
[2023-08-17T00:11:08.526+0300] {standard_task_runner.py:84} INFO - Running: ['***', 'tasks', 'run', 'dag_data_lake', 'is_api_ready_to_consumes', 'manual__2023-08-16T06:32:20.224820+00:00', '--job-id', '5', '--raw', '--subdir', 'DAGS_FOLDER/main.py', '--cfg-path', '/tmp/tmp5uo_eg30']
[2023-08-17T00:11:08.555+0300] {standard_task_runner.py:85} INFO - Job 5: Subtask is_api_ready_to_consumes
[2023-08-17T00:11:09.687+0300] {task_command.py:410} INFO - Running <TaskInstance: dag_data_lake.is_api_ready_to_consumes manual__2023-08-16T06:32:20.224820+00:00 [running]> on host std21006
[2023-08-17T00:11:10.942+0300] {taskinstance.py:1545} INFO - Exporting env vars: AIRFLOW_CTX_DAG_EMAIL='hei.nalisoa@gmail.com,hei.tsirimaholy@gmail.com' AIRFLOW_CTX_DAG_OWNER='***' AIRFLOW_CTX_DAG_ID='dag_data_lake' AIRFLOW_CTX_TASK_ID='is_api_ready_to_consumes' AIRFLOW_CTX_EXECUTION_DATE='2023-08-16T06:32:20.224820+00:00' AIRFLOW_CTX_TRY_NUMBER='1' AIRFLOW_CTX_DAG_RUN_ID='manual__2023-08-16T06:32:20.224820+00:00'
[2023-08-17T00:11:10.960+0300] {http.py:121} INFO - Poking: https://lang-popopy.onrender.com//ping
[2023-08-17T00:11:11.299+0300] {taskinstance.py:1824} ERROR - Task failed with exception
Traceback (most recent call last):
  File "/home/ylan/airflow/venv/lib/python3.9/site-packages/airflow/sensors/base.py", line 225, in execute
    raise e
  File "/home/ylan/airflow/venv/lib/python3.9/site-packages/airflow/sensors/base.py", line 212, in execute
    poke_return = self.poke(context)
  File "/home/ylan/airflow/venv/lib/python3.9/site-packages/airflow/providers/http/sensors/http.py", line 136, in poke
    raise exc
  File "/home/ylan/airflow/venv/lib/python3.9/site-packages/airflow/providers/http/sensors/http.py", line 123, in poke
    response = hook.run(
  File "/home/ylan/airflow/venv/lib/python3.9/site-packages/airflow/providers/http/hooks/http.py", line 145, in run
    session = self.get_conn(headers)
  File "/home/ylan/airflow/venv/lib/python3.9/site-packages/airflow/providers/http/hooks/http.py", line 98, in get_conn
    conn = self.get_connection(self.http_conn_id)
  File "/home/ylan/airflow/venv/lib/python3.9/site-packages/airflow/hooks/base.py", line 72, in get_connection
    conn = Connection.get_connection_from_secrets(conn_id)
  File "/home/ylan/airflow/venv/lib/python3.9/site-packages/airflow/models/connection.py", line 463, in get_connection_from_secrets
    raise AirflowNotFoundException(f"The conn_id `{conn_id}` isn't defined")
airflow.exceptions.AirflowNotFoundException: The conn_id `lang_popy` isn't defined
[2023-08-17T00:11:11.330+0300] {taskinstance.py:1345} INFO - Marking task as UP_FOR_RETRY. dag_id=dag_data_lake, task_id=is_api_ready_to_consumes, execution_date=20230816T063220, start_date=20230816T211108, end_date=20230816T211111
[2023-08-17T00:11:11.433+0300] {standard_task_runner.py:104} ERROR - Failed to execute job 5 for task is_api_ready_to_consumes (The conn_id `lang_popy` isn't defined; 234163)
[2023-08-17T00:11:11.501+0300] {local_task_job_runner.py:225} INFO - Task exited with return code 1
[2023-08-17T00:11:11.750+0300] {taskinstance.py:2653} INFO - 0 downstream tasks scheduled from follow-on schedule check
